<?xml version="1.0" ?>
<robot name="NadMobility" xmlns:xacro="http://ros.org/wiki/xacro">
    <!-- base_footprint-->
    <link name="base_footprint">
        <inertial>
            <mass value="0.0001"/>
            <origin xyz="0 0 0"/>
            <inertia ixx="0.0001" ixy="0.0" ixz="0.0"
                   iyy="0.0001" iyz="0.0"
                   izz="0.0001"/>
        </inertial>
        <visual>
          <geometry>
              <box size="0.001 0.001 0.001"/>
          </geometry>
          <origin rpy="0 0 0" xyz="0 0 0"/>
        </visual>
    </link>

    <!-- base_link-->
    <link name="base_link">
        <pose>0 0 0 0 0 0</pose>
        <inertial>
            <mass value="10.0"/>
            <origin xyz="0.0 0 0.1" rpy=" 0 0 0"/>
        <inertia
          ixx="0.5" ixy="0" ixz="0"
          iyy="1.0" iyz="0"
          izz="0.1"
        />
        </inertial>

        <collision name='collision'>
        <geometry>
            <box size="0.001 0.001 0.001"/>
        </geometry>
        </collision>

        <visual name='base_link_visual'>
            <origin xyz="0 0 0" rpy=" 0 0 0"/>
            <geometry>
                <box size="0.001 0.001 0.001"/>
            </geometry>
        </visual>

    </link>

    <!-- left_wheel-->
    <link name="left_wheel">
        <collision name="collision">
              <origin xyz="0 0 0" rpy="0 1.5707 1.5707"/>
              <geometry>
                <box size="0.001 0.001 0.001"/>
              </geometry>
        </collision>
            <visual name="left_wheel_visual">
              <origin xyz="0 0 0" rpy="0 1.5707 1.5707"/>
              <geometry>
                <box size="0.001 0.001 0.001"/>
              </geometry>>
            </visual>
        <inertial>
              <origin xyz="0 0 0" rpy="0 1.5707 1.5707"/>
              <mass value="5"/>
              <geometry>
                <box size="0.001 0.001 0.001"/>
              </geometry>
              <inertia
                ixx="1.0" ixy="0.0" ixz="0.0"
                iyy="1.0" iyz="0.0"
                izz="1.0"/>
        </inertial>
    </link>

    <!-- right_wheel-->
    <link name="right_wheel">
        <collision name="collision">
          <origin xyz="0 0 0" rpy="0 1.5707 1.5707"/>
          <geometry>
            <box size="0.001 0.001 0.001"/>
          </geometry>
        </collision>

        <visual name="right_wheel_visual">
          <origin xyz="0 0 0" rpy="0 1.5707 1.5707"/>
          <geometry>
            <box size="0.001 0.001 0.001"/>
          </geometry>
        </visual>
        <inertial>
          <origin xyz="0 0 0" rpy="0 1.5707 1.5707"/>
          <mass value="5"/>
          <geometry>
            <box size="0.001 0.001 0.001"/>
          </geometry>          <inertia
            ixx="1.0" ixy="0.0" ixz="0.0"
            iyy="1.0" iyz="0.0"
            izz="1.0"/>
        </inertial>
    </link>

    <!--&lt;!&ndash; laser_link&ndash;&gt;-->
    <!--<link name="laser_link">-->
        <!--<collision name="collision">-->
          <!--<origin xyz="0 0 0" rpy="0 1.5707 1.5707"/>-->
          <!--<geometry>-->
            <!--<box size="0.001 0.001 0.001"/>-->
          <!--</geometry>-->
        <!--</collision>-->

        <!--<visual name="right_wheel_visual">-->
          <!--<origin xyz="0 0 0" rpy="0 1.5707 1.5707"/>-->
          <!--<geometry>-->
            <!--<box size="0.001 0.001 0.001"/>-->
          <!--</geometry>-->
        <!--</visual>-->
        <!--<inertial>-->
          <!--<origin xyz="0 0 0" rpy="0 1.5707 1.5707"/>-->
          <!--<mass value="5"/>-->
          <!--<geometry>-->
            <!--<box size="0.001 0.001 0.001"/>-->
          <!--</geometry>          <inertia-->
            <!--ixx="1.0" ixy="0.0" ixz="0.0"-->
            <!--iyy="1.0" iyz="0.0"-->
            <!--izz="1.0"/>-->
        <!--</inertial>-->
    <!--</link>-->



    <joint name="base_footprint_joint" type="fixed">
        <parent link="base_footprint"/>
        <child link="base_link"/>
        <origin xyz="0 0 0.0475" rpy="0 0 0"/>
    </joint>

    <!--<joint name="laser_joint" type="fixed">-->
        <!--<parent link="base_link"/>-->
        <!--<child link="laser_link"/>-->
        <!--<origin xyz="0.123 0 0.224" rpy="-3.14159 0 0"/>-->
    <!--</joint>-->

    <joint name="left_wheel_joint" type="continuous">
        <origin xyz="0 0.17 0" rpy="0 0 0"/>
        <child link="left_wheel"/>
        <parent link="base_link"/>
        <axis xyz="0 1 0" rpy="0 0 0"/>
        <limit effort="100" velocity="100"/>
        <joint_properties damping="0.0" friction="0.0"/>
    </joint>

    <joint name="right_wheel_joint" type="continuous">
        <origin xyz="0 -0.17 0" rpy="0 0 0"/>
        <child link="right_wheel"/>
        <parent link="base_link"/>
        <axis xyz="0 1 0" rpy="0 0 0"/>
        <limit effort="100" velocity="100"/>
        <joint_properties damping="0.0" friction="0.0"/>
    </joint>
</robot>
